<?xml version="1.0"?>
<robot name="basit_robot">
  <link name="base_link">
    <visual>
      <geometry>
        <box size="0.6 0.4 0.2"/>
      </geometry>
    </visual>
  </link>

  <link name="tekerlek">
    <visual>
      <geometry>
        <cylinder length="0.05" radius="0.1"/>
      </geometry>
    </visual>
  </link>

  <joint name="govde_tekerlek_baglantisi" type="continuous">
    <parent link="base_link"/>
    <child link="tekerlek"/>
    <origin xyz="0.2 0.25 0" rpy="1.57 0 0"/>
    <axis xyz="0 0 1"/>
  </joint>
</robot>